2025-08-29 13:17:09,137 - INFO - Application starting...
2025-08-29 13:17:09,577 - DEBUG - Starting new HTTPS connection (1): api.telegra.ph:443
2025-08-29 13:17:09,814 - DEBUG - https://api.telegra.ph:443 "POST /createAccount/ HTTP/1.1" 200 213
2025-08-29 13:17:24,761 - DEBUG - Not in REPL -> leaving logger event level as is.
2025-08-29 13:17:24,774 - DEBUG - Looking for locale `en_US` in provider `faker.providers.address`.
2025-08-29 13:17:24,782 - DEBUG - Provider `faker.providers.address` has been localized to `en_US`.
2025-08-29 13:17:24,786 - DEBUG - Looking for locale `en_US` in provider `faker.providers.automotive`.
2025-08-29 13:17:24,791 - DEBUG - Provider `faker.providers.automotive` has been localized to `en_US`.
2025-08-29 13:17:24,793 - DEBUG - Looking for locale `en_US` in provider `faker.providers.bank`.
2025-08-29 13:17:24,797 - DEBUG - Specified locale `en_US` is not available for provider `faker.providers.bank`. Locale reset to `en_GB` for this provider.
2025-08-29 13:17:24,798 - DEBUG - Looking for locale `en_US` in provider `faker.providers.barcode`.
2025-08-29 13:17:24,799 - DEBUG - Provider `faker.providers.barcode` has been localized to `en_US`.
2025-08-29 13:17:24,802 - DEBUG - Looking for locale `en_US` in provider `faker.providers.color`.
2025-08-29 13:17:24,806 - DEBUG - Provider `faker.providers.color` has been localized to `en_US`.
2025-08-29 13:17:24,808 - DEBUG - Looking for locale `en_US` in provider `faker.providers.company`.
2025-08-29 13:17:24,812 - DEBUG - Provider `faker.providers.company` has been localized to `en_US`.
2025-08-29 13:17:24,813 - DEBUG - Looking for locale `en_US` in provider `faker.providers.credit_card`.
2025-08-29 13:17:24,814 - DEBUG - Provider `faker.providers.credit_card` has been localized to `en_US`.
2025-08-29 13:17:24,817 - DEBUG - Looking for locale `en_US` in provider `faker.providers.currency`.
2025-08-29 13:17:24,822 - DEBUG - Provider `faker.providers.currency` has been localized to `en_US`.
2025-08-29 13:17:24,824 - DEBUG - Looking for locale `en_US` in provider `faker.providers.date_time`.
2025-08-29 13:17:24,832 - DEBUG - Provider `faker.providers.date_time` has been localized to `en_US`.
2025-08-29 13:17:24,834 - DEBUG - Provider `faker.providers.doi` does not feature localization. Specified locale `en_US` is not utilized for this provider.
2025-08-29 13:17:24,835 - DEBUG - Provider `faker.providers.emoji` does not feature localization. Specified locale `en_US` is not utilized for this provider.
2025-08-29 13:17:24,835 - DEBUG - Provider `faker.providers.file` does not feature localization. Specified locale `en_US` is not utilized for this provider.
2025-08-29 13:17:24,835 - DEBUG - Looking for locale `en_US` in provider `faker.providers.geo`.
2025-08-29 13:17:24,837 - DEBUG - Provider `faker.providers.geo` has been localized to `en_US`.
2025-08-29 13:17:24,839 - DEBUG - Looking for locale `en_US` in provider `faker.providers.internet`.
2025-08-29 13:17:24,845 - DEBUG - Provider `faker.providers.internet` has been localized to `en_US`.
2025-08-29 13:17:24,847 - DEBUG - Looking for locale `en_US` in provider `faker.providers.isbn`.
2025-08-29 13:17:24,848 - DEBUG - Provider `faker.providers.isbn` has been localized to `en_US`.
2025-08-29 13:17:24,849 - DEBUG - Looking for locale `en_US` in provider `faker.providers.job`.
2025-08-29 13:17:24,855 - DEBUG - Provider `faker.providers.job` has been localized to `en_US`.
2025-08-29 13:17:24,857 - DEBUG - Looking for locale `en_US` in provider `faker.providers.lorem`.
2025-08-29 13:17:24,865 - DEBUG - Provider `faker.providers.lorem` has been localized to `en_US`.
2025-08-29 13:17:24,866 - DEBUG - Looking for locale `en_US` in provider `faker.providers.misc`.
2025-08-29 13:17:24,866 - DEBUG - Provider `faker.providers.misc` has been localized to `en_US`.
2025-08-29 13:17:24,869 - DEBUG - Looking for locale `en_US` in provider `faker.providers.passport`.
2025-08-29 13:17:24,870 - DEBUG - Provider `faker.providers.passport` has been localized to `en_US`.
2025-08-29 13:17:24,871 - DEBUG - Looking for locale `en_US` in provider `faker.providers.person`.
2025-08-29 13:17:24,887 - DEBUG - Provider `faker.providers.person` has been localized to `en_US`.
2025-08-29 13:17:24,893 - DEBUG - Looking for locale `en_US` in provider `faker.providers.phone_number`.
2025-08-29 13:17:24,902 - DEBUG - Provider `faker.providers.phone_number` has been localized to `en_US`.
2025-08-29 13:17:24,904 - DEBUG - Provider `faker.providers.profile` does not feature localization. Specified locale `en_US` is not utilized for this provider.
2025-08-29 13:17:24,904 - DEBUG - Provider `faker.providers.python` does not feature localization. Specified locale `en_US` is not utilized for this provider.
2025-08-29 13:17:24,904 - DEBUG - Provider `faker.providers.sbn` does not feature localization. Specified locale `en_US` is not utilized for this provider.
2025-08-29 13:17:24,904 - DEBUG - Looking for locale `en_US` in provider `faker.providers.ssn`.
2025-08-29 13:17:24,912 - DEBUG - Provider `faker.providers.ssn` has been localized to `en_US`.
2025-08-29 13:17:24,914 - DEBUG - Provider `faker.providers.user_agent` does not feature localization. Specified locale `en_US` is not utilized for this provider.
2025-08-29 13:17:31,083 - INFO - MainWindow.__init__ started.
2025-08-29 13:17:31,680 - INFO - MainWindow.__init__ finished.
2025-08-29 13:17:45,582 - DEBUG - Starting new HTTPS connection (1): api.proxynova.com:443
2025-08-29 13:17:45,954 - ERROR - Error in worker thread for search_by_number: maximum recursion depth exceeded
Traceback (most recent call last):
  File "C:\Users\mikromark\Desktop\laitoxx 2.2.1\gui.py", line 378, in run_tool
    with contextlib.redirect_stdout(output_stream): self.func()
                                                    ^^^^^^^^^^^
  File "C:\Users\mikromark\Desktop\laitoxx 2.2.1\script\tools\user_search_by_phone.py", line 53, in search_by_number
    response = requests.get(f"https://api.proxynova.com/comb?query={phone_suffix}&start=0&limit=100", allow_redirects=False, timeout=10)
               ^^^^^^^^^^^^^^^^^^^^^^^^^^^^^^^^^^^^^^^^^^^^^^^^^^^^^^^^^^^^^^^^^^^^^^^^^^^^^^^^^^^^^^^^^^^^^^^^^^^^^^^^^^^^^^^^^^^^^^^^^
  File "C:\Users\mikromark\AppData\Local\Programs\Python\Python311\Lib\site-packages\requests\api.py", line 73, in get
    return request("get", url, params=params, **kwargs)
           ^^^^^^^^^^^^^^^^^^^^^^^^^^^^^^^^^^^^^^^^^^^^
  File "C:\Users\mikromark\AppData\Local\Programs\Python\Python311\Lib\site-packages\requests\api.py", line 59, in request
    return session.request(method=method, url=url, **kwargs)
           ^^^^^^^^^^^^^^^^^^^^^^^^^^^^^^^^^^^^^^^^^^^^^^^^^
  File "C:\Users\mikromark\AppData\Local\Programs\Python\Python311\Lib\site-packages\requests\sessions.py", line 589, in request
    resp = self.send(prep, **send_kwargs)
           ^^^^^^^^^^^^^^^^^^^^^^^^^^^^^^
  File "C:\Users\mikromark\AppData\Local\Programs\Python\Python311\Lib\site-packages\requests\sessions.py", line 703, in send
    r = adapter.send(request, **kwargs)
        ^^^^^^^^^^^^^^^^^^^^^^^^^^^^^^^
  File "C:\Users\mikromark\AppData\Local\Programs\Python\Python311\Lib\site-packages\requests\adapters.py", line 644, in send
    resp = conn.urlopen(
           ^^^^^^^^^^^^^
  File "C:\Users\mikromark\AppData\Local\Programs\Python\Python311\Lib\site-packages\urllib3\connectionpool.py", line 787, in urlopen
    response = self._make_request(
               ^^^^^^^^^^^^^^^^^^^
  File "C:\Users\mikromark\AppData\Local\Programs\Python\Python311\Lib\site-packages\urllib3\connectionpool.py", line 464, in _make_request
    self._validate_conn(conn)
  File "C:\Users\mikromark\AppData\Local\Programs\Python\Python311\Lib\site-packages\urllib3\connectionpool.py", line 1093, in _validate_conn
    conn.connect()
  File "C:\Users\mikromark\AppData\Local\Programs\Python\Python311\Lib\site-packages\urllib3\connection.py", line 790, in connect
    sock_and_verified = _ssl_wrap_socket_and_match_hostname(
                        ^^^^^^^^^^^^^^^^^^^^^^^^^^^^^^^^^^^^
  File "C:\Users\mikromark\AppData\Local\Programs\Python\Python311\Lib\site-packages\urllib3\connection.py", line 922, in _ssl_wrap_socket_and_match_hostname
    context = create_urllib3_context(
              ^^^^^^^^^^^^^^^^^^^^^^^
  File "C:\Users\mikromark\AppData\Local\Programs\Python\Python311\Lib\site-packages\urllib3\util\ssl_.py", line 303, in create_urllib3_context
    context.minimum_version = TLSVersion.TLSv1_2
    ^^^^^^^^^^^^^^^^^^^^^^^
  File "C:\Users\mikromark\AppData\Local\Programs\Python\Python311\Lib\ssl.py", line 608, in minimum_version
    super(SSLContext, SSLContext).minimum_version.__set__(self, value)
  File "C:\Users\mikromark\AppData\Local\Programs\Python\Python311\Lib\ssl.py", line 608, in minimum_version
    super(SSLContext, SSLContext).minimum_version.__set__(self, value)
  File "C:\Users\mikromark\AppData\Local\Programs\Python\Python311\Lib\ssl.py", line 608, in minimum_version
    super(SSLContext, SSLContext).minimum_version.__set__(self, value)
  [Previous line repeated 489 more times]
  File "C:\Users\mikromark\AppData\Local\Programs\Python\Python311\Lib\ssl.py", line 606, in minimum_version
    if value == TLSVersion.SSLv3:
                ^^^^^^^^^^^^^^^^
RecursionError: maximum recursion depth exceeded
2025-08-29 13:18:13,793 - DEBUG - Starting new HTTP connection (1): ipwho.is:80
2025-08-29 13:18:13,885 - DEBUG - http://ipwho.is:80 "GET /1.1.1.1 HTTP/1.1" 200 None
2025-08-29 13:18:46,371 - DEBUG - Starting new HTTPS connection (1): gmail-osint.activetk.jp:443
2025-08-29 13:18:46,576 - ERROR - Error in worker thread for gmail_osint: maximum recursion depth exceeded
Traceback (most recent call last):
  File "C:\Users\mikromark\Desktop\laitoxx 2.2.1\gui.py", line 378, in run_tool
    with contextlib.redirect_stdout(output_stream): self.func()
                                                    ^^^^^^^^^^^
  File "C:\Users\mikromark\Desktop\laitoxx 2.2.1\script\tools\gmail_osint.py", line 24, in gmail_osint
    response = requests.get(url, timeout=15)
               ^^^^^^^^^^^^^^^^^^^^^^^^^^^^^
  File "C:\Users\mikromark\AppData\Local\Programs\Python\Python311\Lib\site-packages\requests\api.py", line 73, in get
    return request("get", url, params=params, **kwargs)
           ^^^^^^^^^^^^^^^^^^^^^^^^^^^^^^^^^^^^^^^^^^^^
  File "C:\Users\mikromark\AppData\Local\Programs\Python\Python311\Lib\site-packages\requests\api.py", line 59, in request
    return session.request(method=method, url=url, **kwargs)
           ^^^^^^^^^^^^^^^^^^^^^^^^^^^^^^^^^^^^^^^^^^^^^^^^^
  File "C:\Users\mikromark\AppData\Local\Programs\Python\Python311\Lib\site-packages\requests\sessions.py", line 589, in request
    resp = self.send(prep, **send_kwargs)
           ^^^^^^^^^^^^^^^^^^^^^^^^^^^^^^
  File "C:\Users\mikromark\AppData\Local\Programs\Python\Python311\Lib\site-packages\requests\sessions.py", line 703, in send
    r = adapter.send(request, **kwargs)
        ^^^^^^^^^^^^^^^^^^^^^^^^^^^^^^^
  File "C:\Users\mikromark\AppData\Local\Programs\Python\Python311\Lib\site-packages\requests\adapters.py", line 644, in send
    resp = conn.urlopen(
           ^^^^^^^^^^^^^
  File "C:\Users\mikromark\AppData\Local\Programs\Python\Python311\Lib\site-packages\urllib3\connectionpool.py", line 787, in urlopen
    response = self._make_request(
               ^^^^^^^^^^^^^^^^^^^
  File "C:\Users\mikromark\AppData\Local\Programs\Python\Python311\Lib\site-packages\urllib3\connectionpool.py", line 464, in _make_request
    self._validate_conn(conn)
  File "C:\Users\mikromark\AppData\Local\Programs\Python\Python311\Lib\site-packages\urllib3\connectionpool.py", line 1093, in _validate_conn
    conn.connect()
  File "C:\Users\mikromark\AppData\Local\Programs\Python\Python311\Lib\site-packages\urllib3\connection.py", line 790, in connect
    sock_and_verified = _ssl_wrap_socket_and_match_hostname(
                        ^^^^^^^^^^^^^^^^^^^^^^^^^^^^^^^^^^^^
  File "C:\Users\mikromark\AppData\Local\Programs\Python\Python311\Lib\site-packages\urllib3\connection.py", line 922, in _ssl_wrap_socket_and_match_hostname
    context = create_urllib3_context(
              ^^^^^^^^^^^^^^^^^^^^^^^
  File "C:\Users\mikromark\AppData\Local\Programs\Python\Python311\Lib\site-packages\urllib3\util\ssl_.py", line 303, in create_urllib3_context
    context.minimum_version = TLSVersion.TLSv1_2
    ^^^^^^^^^^^^^^^^^^^^^^^
  File "C:\Users\mikromark\AppData\Local\Programs\Python\Python311\Lib\ssl.py", line 608, in minimum_version
    super(SSLContext, SSLContext).minimum_version.__set__(self, value)
  File "C:\Users\mikromark\AppData\Local\Programs\Python\Python311\Lib\ssl.py", line 608, in minimum_version
    super(SSLContext, SSLContext).minimum_version.__set__(self, value)
  File "C:\Users\mikromark\AppData\Local\Programs\Python\Python311\Lib\ssl.py", line 608, in minimum_version
    super(SSLContext, SSLContext).minimum_version.__set__(self, value)
  [Previous line repeated 489 more times]
  File "C:\Users\mikromark\AppData\Local\Programs\Python\Python311\Lib\ssl.py", line 606, in minimum_version
    if value == TLSVersion.SSLv3:
                ^^^^^^^^^^^^^^^^
RecursionError: maximum recursion depth exceeded
2025-08-29 13:19:59,782 - DEBUG - Starting new HTTPS connection (1): api.macvendors.com:443
2025-08-29 13:19:59,904 - ERROR - Error in worker thread for search_mac_address: maximum recursion depth exceeded
Traceback (most recent call last):
  File "C:\Users\mikromark\Desktop\laitoxx 2.2.1\gui.py", line 378, in run_tool
    with contextlib.redirect_stdout(output_stream): self.func()
                                                    ^^^^^^^^^^^
  File "C:\Users\mikromark\Desktop\laitoxx 2.2.1\script\tools\mac_lookup.py", line 28, in search_mac_address
    response = requests.get(url, timeout=10)
               ^^^^^^^^^^^^^^^^^^^^^^^^^^^^^
  File "C:\Users\mikromark\AppData\Local\Programs\Python\Python311\Lib\site-packages\requests\api.py", line 73, in get
    return request("get", url, params=params, **kwargs)
           ^^^^^^^^^^^^^^^^^^^^^^^^^^^^^^^^^^^^^^^^^^^^
  File "C:\Users\mikromark\AppData\Local\Programs\Python\Python311\Lib\site-packages\requests\api.py", line 59, in request
    return session.request(method=method, url=url, **kwargs)
           ^^^^^^^^^^^^^^^^^^^^^^^^^^^^^^^^^^^^^^^^^^^^^^^^^
  File "C:\Users\mikromark\AppData\Local\Programs\Python\Python311\Lib\site-packages\requests\sessions.py", line 589, in request
    resp = self.send(prep, **send_kwargs)
           ^^^^^^^^^^^^^^^^^^^^^^^^^^^^^^
  File "C:\Users\mikromark\AppData\Local\Programs\Python\Python311\Lib\site-packages\requests\sessions.py", line 703, in send
    r = adapter.send(request, **kwargs)
        ^^^^^^^^^^^^^^^^^^^^^^^^^^^^^^^
  File "C:\Users\mikromark\AppData\Local\Programs\Python\Python311\Lib\site-packages\requests\adapters.py", line 644, in send
    resp = conn.urlopen(
           ^^^^^^^^^^^^^
  File "C:\Users\mikromark\AppData\Local\Programs\Python\Python311\Lib\site-packages\urllib3\connectionpool.py", line 787, in urlopen
    response = self._make_request(
               ^^^^^^^^^^^^^^^^^^^
  File "C:\Users\mikromark\AppData\Local\Programs\Python\Python311\Lib\site-packages\urllib3\connectionpool.py", line 464, in _make_request
    self._validate_conn(conn)
  File "C:\Users\mikromark\AppData\Local\Programs\Python\Python311\Lib\site-packages\urllib3\connectionpool.py", line 1093, in _validate_conn
    conn.connect()
  File "C:\Users\mikromark\AppData\Local\Programs\Python\Python311\Lib\site-packages\urllib3\connection.py", line 790, in connect
    sock_and_verified = _ssl_wrap_socket_and_match_hostname(
                        ^^^^^^^^^^^^^^^^^^^^^^^^^^^^^^^^^^^^
  File "C:\Users\mikromark\AppData\Local\Programs\Python\Python311\Lib\site-packages\urllib3\connection.py", line 922, in _ssl_wrap_socket_and_match_hostname
    context = create_urllib3_context(
              ^^^^^^^^^^^^^^^^^^^^^^^
  File "C:\Users\mikromark\AppData\Local\Programs\Python\Python311\Lib\site-packages\urllib3\util\ssl_.py", line 303, in create_urllib3_context
    context.minimum_version = TLSVersion.TLSv1_2
    ^^^^^^^^^^^^^^^^^^^^^^^
  File "C:\Users\mikromark\AppData\Local\Programs\Python\Python311\Lib\ssl.py", line 608, in minimum_version
    super(SSLContext, SSLContext).minimum_version.__set__(self, value)
  File "C:\Users\mikromark\AppData\Local\Programs\Python\Python311\Lib\ssl.py", line 608, in minimum_version
    super(SSLContext, SSLContext).minimum_version.__set__(self, value)
  File "C:\Users\mikromark\AppData\Local\Programs\Python\Python311\Lib\ssl.py", line 608, in minimum_version
    super(SSLContext, SSLContext).minimum_version.__set__(self, value)
  [Previous line repeated 489 more times]
  File "C:\Users\mikromark\AppData\Local\Programs\Python\Python311\Lib\ssl.py", line 606, in minimum_version
    if value == TLSVersion.SSLv3:
                ^^^^^^^^^^^^^^^^
RecursionError: maximum recursion depth exceeded
2025-08-29 13:20:35,466 - DEBUG - Starting new HTTPS connection (1): crt.sh:443
2025-08-29 13:20:35,785 - ERROR - Error in worker thread for find_subdomains: maximum recursion depth exceeded
Traceback (most recent call last):
  File "C:\Users\mikromark\Desktop\laitoxx 2.2.1\gui.py", line 378, in run_tool
    with contextlib.redirect_stdout(output_stream): self.func()
                                                    ^^^^^^^^^^^
  File "C:\Users\mikromark\Desktop\laitoxx 2.2.1\script\tools\subdomain_finder.py", line 26, in find_subdomains
    response = requests.get(url, timeout=20)
               ^^^^^^^^^^^^^^^^^^^^^^^^^^^^^
  File "C:\Users\mikromark\AppData\Local\Programs\Python\Python311\Lib\site-packages\requests\api.py", line 73, in get
    return request("get", url, params=params, **kwargs)
           ^^^^^^^^^^^^^^^^^^^^^^^^^^^^^^^^^^^^^^^^^^^^
  File "C:\Users\mikromark\AppData\Local\Programs\Python\Python311\Lib\site-packages\requests\api.py", line 59, in request
    return session.request(method=method, url=url, **kwargs)
           ^^^^^^^^^^^^^^^^^^^^^^^^^^^^^^^^^^^^^^^^^^^^^^^^^
  File "C:\Users\mikromark\AppData\Local\Programs\Python\Python311\Lib\site-packages\requests\sessions.py", line 589, in request
    resp = self.send(prep, **send_kwargs)
           ^^^^^^^^^^^^^^^^^^^^^^^^^^^^^^
  File "C:\Users\mikromark\AppData\Local\Programs\Python\Python311\Lib\site-packages\requests\sessions.py", line 703, in send
    r = adapter.send(request, **kwargs)
        ^^^^^^^^^^^^^^^^^^^^^^^^^^^^^^^
  File "C:\Users\mikromark\AppData\Local\Programs\Python\Python311\Lib\site-packages\requests\adapters.py", line 644, in send
    resp = conn.urlopen(
           ^^^^^^^^^^^^^
  File "C:\Users\mikromark\AppData\Local\Programs\Python\Python311\Lib\site-packages\urllib3\connectionpool.py", line 787, in urlopen
    response = self._make_request(
               ^^^^^^^^^^^^^^^^^^^
  File "C:\Users\mikromark\AppData\Local\Programs\Python\Python311\Lib\site-packages\urllib3\connectionpool.py", line 464, in _make_request
    self._validate_conn(conn)
  File "C:\Users\mikromark\AppData\Local\Programs\Python\Python311\Lib\site-packages\urllib3\connectionpool.py", line 1093, in _validate_conn
    conn.connect()
  File "C:\Users\mikromark\AppData\Local\Programs\Python\Python311\Lib\site-packages\urllib3\connection.py", line 790, in connect
    sock_and_verified = _ssl_wrap_socket_and_match_hostname(
                        ^^^^^^^^^^^^^^^^^^^^^^^^^^^^^^^^^^^^
  File "C:\Users\mikromark\AppData\Local\Programs\Python\Python311\Lib\site-packages\urllib3\connection.py", line 922, in _ssl_wrap_socket_and_match_hostname
    context = create_urllib3_context(
              ^^^^^^^^^^^^^^^^^^^^^^^
  File "C:\Users\mikromark\AppData\Local\Programs\Python\Python311\Lib\site-packages\urllib3\util\ssl_.py", line 303, in create_urllib3_context
    context.minimum_version = TLSVersion.TLSv1_2
    ^^^^^^^^^^^^^^^^^^^^^^^
  File "C:\Users\mikromark\AppData\Local\Programs\Python\Python311\Lib\ssl.py", line 608, in minimum_version
    super(SSLContext, SSLContext).minimum_version.__set__(self, value)
  File "C:\Users\mikromark\AppData\Local\Programs\Python\Python311\Lib\ssl.py", line 608, in minimum_version
    super(SSLContext, SSLContext).minimum_version.__set__(self, value)
  File "C:\Users\mikromark\AppData\Local\Programs\Python\Python311\Lib\ssl.py", line 608, in minimum_version
    super(SSLContext, SSLContext).minimum_version.__set__(self, value)
  [Previous line repeated 489 more times]
  File "C:\Users\mikromark\AppData\Local\Programs\Python\Python311\Lib\ssl.py", line 606, in minimum_version
    if value == TLSVersion.SSLv3:
                ^^^^^^^^^^^^^^^^
RecursionError: maximum recursion depth exceeded
2025-08-29 13:20:42,385 - DEBUG - Starting new HTTPS connection (1): crt.sh:443
2025-08-29 13:20:42,456 - ERROR - Error in worker thread for find_subdomains: maximum recursion depth exceeded
Traceback (most recent call last):
  File "C:\Users\mikromark\Desktop\laitoxx 2.2.1\gui.py", line 378, in run_tool
    with contextlib.redirect_stdout(output_stream): self.func()
                                                    ^^^^^^^^^^^
  File "C:\Users\mikromark\Desktop\laitoxx 2.2.1\script\tools\subdomain_finder.py", line 26, in find_subdomains
    response = requests.get(url, timeout=20)
               ^^^^^^^^^^^^^^^^^^^^^^^^^^^^^
  File "C:\Users\mikromark\AppData\Local\Programs\Python\Python311\Lib\site-packages\requests\api.py", line 73, in get
    return request("get", url, params=params, **kwargs)
           ^^^^^^^^^^^^^^^^^^^^^^^^^^^^^^^^^^^^^^^^^^^^
  File "C:\Users\mikromark\AppData\Local\Programs\Python\Python311\Lib\site-packages\requests\api.py", line 59, in request
    return session.request(method=method, url=url, **kwargs)
           ^^^^^^^^^^^^^^^^^^^^^^^^^^^^^^^^^^^^^^^^^^^^^^^^^
  File "C:\Users\mikromark\AppData\Local\Programs\Python\Python311\Lib\site-packages\requests\sessions.py", line 589, in request
    resp = self.send(prep, **send_kwargs)
           ^^^^^^^^^^^^^^^^^^^^^^^^^^^^^^
  File "C:\Users\mikromark\AppData\Local\Programs\Python\Python311\Lib\site-packages\requests\sessions.py", line 703, in send
    r = adapter.send(request, **kwargs)
        ^^^^^^^^^^^^^^^^^^^^^^^^^^^^^^^
  File "C:\Users\mikromark\AppData\Local\Programs\Python\Python311\Lib\site-packages\requests\adapters.py", line 644, in send
    resp = conn.urlopen(
           ^^^^^^^^^^^^^
  File "C:\Users\mikromark\AppData\Local\Programs\Python\Python311\Lib\site-packages\urllib3\connectionpool.py", line 787, in urlopen
    response = self._make_request(
               ^^^^^^^^^^^^^^^^^^^
  File "C:\Users\mikromark\AppData\Local\Programs\Python\Python311\Lib\site-packages\urllib3\connectionpool.py", line 464, in _make_request
    self._validate_conn(conn)
  File "C:\Users\mikromark\AppData\Local\Programs\Python\Python311\Lib\site-packages\urllib3\connectionpool.py", line 1093, in _validate_conn
    conn.connect()
  File "C:\Users\mikromark\AppData\Local\Programs\Python\Python311\Lib\site-packages\urllib3\connection.py", line 790, in connect
    sock_and_verified = _ssl_wrap_socket_and_match_hostname(
                        ^^^^^^^^^^^^^^^^^^^^^^^^^^^^^^^^^^^^
  File "C:\Users\mikromark\AppData\Local\Programs\Python\Python311\Lib\site-packages\urllib3\connection.py", line 922, in _ssl_wrap_socket_and_match_hostname
    context = create_urllib3_context(
              ^^^^^^^^^^^^^^^^^^^^^^^
  File "C:\Users\mikromark\AppData\Local\Programs\Python\Python311\Lib\site-packages\urllib3\util\ssl_.py", line 303, in create_urllib3_context
    context.minimum_version = TLSVersion.TLSv1_2
    ^^^^^^^^^^^^^^^^^^^^^^^
  File "C:\Users\mikromark\AppData\Local\Programs\Python\Python311\Lib\ssl.py", line 608, in minimum_version
    super(SSLContext, SSLContext).minimum_version.__set__(self, value)
  File "C:\Users\mikromark\AppData\Local\Programs\Python\Python311\Lib\ssl.py", line 608, in minimum_version
    super(SSLContext, SSLContext).minimum_version.__set__(self, value)
  File "C:\Users\mikromark\AppData\Local\Programs\Python\Python311\Lib\ssl.py", line 608, in minimum_version
    super(SSLContext, SSLContext).minimum_version.__set__(self, value)
  [Previous line repeated 489 more times]
  File "C:\Users\mikromark\AppData\Local\Programs\Python\Python311\Lib\ssl.py", line 606, in minimum_version
    if value == TLSVersion.SSLv3:
                ^^^^^^^^^^^^^^^^
RecursionError: maximum recursion depth exceeded
2025-08-29 13:21:25,925 - DEBUG - Starting new HTTPS connection (1): t.me:443
2025-08-29 13:21:34,369 - DEBUG - Starting new HTTPS connection (1): t.me:443
2025-08-29 13:21:58,693 - DEBUG - Starting new HTTPS connection (1): t.me:443
2025-08-29 13:22:02,783 - DEBUG - Starting new HTTPS connection (1): twitter.com:443
2025-08-29 13:22:02,786 - DEBUG - Starting new HTTPS connection (1): www.instagram.com:443
2025-08-29 13:22:02,788 - DEBUG - Starting new HTTPS connection (1): www.facebook.com:443
2025-08-29 13:22:02,790 - DEBUG - Starting new HTTPS connection (1): t.me:443
2025-08-29 13:22:02,792 - DEBUG - Starting new HTTPS connection (1): www.youtube.com:443
2025-08-29 13:22:02,793 - DEBUG - Starting new HTTPS connection (1): www.reddit.com:443
2025-08-29 13:22:02,795 - DEBUG - Starting new HTTPS connection (1): www.roblox.com:443
2025-08-29 13:22:02,796 - DEBUG - Starting new HTTPS connection (1): vk.com:443
2025-08-29 13:22:02,798 - DEBUG - Starting new HTTPS connection (1): www.tiktok.com:443
2025-08-29 13:22:02,800 - DEBUG - Starting new HTTPS connection (1): www.pinterest.com:443
2025-08-29 13:22:02,801 - DEBUG - Starting new HTTPS connection (1): github.com:443
2025-08-29 13:22:02,802 - DEBUG - Starting new HTTPS connection (1): www.twitch.tv:443
2025-08-29 13:22:02,804 - DEBUG - Starting new HTTPS connection (1): www.linkedin.com:443
2025-08-29 13:22:02,805 - DEBUG - Starting new HTTPS connection (1): www.snapchat.com:443
2025-08-29 13:22:02,807 - DEBUG - Starting new HTTPS connection (1): flickr.com:443
2025-08-29 13:22:02,807 - DEBUG - Starting new HTTPS connection (1): vimeo.com:443
2025-08-29 13:22:02,809 - DEBUG - Starting new HTTPS connection (1): soundcloud.com:443
2025-08-29 13:22:02,811 - DEBUG - Starting new HTTPS connection (1): medium.com:443
2025-08-29 13:22:02,813 - DEBUG - Starting new HTTPS connection (1): www.patreon.com:443
2025-08-29 13:22:02,816 - DEBUG - Starting new HTTPS connection (1): open.spotify.com:443
2025-08-29 13:22:02,852 - DEBUG - Starting new HTTPS connection (1): steamcommunity.com:443
2025-08-29 13:22:02,861 - DEBUG - Starting new HTTPS connection (1): mikromark.tumblr.com:443
2025-08-29 13:22:02,878 - DEBUG - Starting new HTTPS connection (1): mikromark.wordpress.com:443
2025-08-29 13:22:02,881 - DEBUG - Starting new HTTPS connection (1): mikromark.deviantart.com:443
2025-08-29 13:22:02,892 - DEBUG - Starting new HTTPS connection (1): pastebin.com:443
2025-08-29 13:22:02,894 - DEBUG - Starting new HTTPS connection (1): keybase.io:443
2025-08-29 13:22:02,900 - DEBUG - Starting new HTTPS connection (1): dribbble.com:443
2025-08-29 13:22:02,907 - DEBUG - Starting new HTTPS connection (1): www.behance.net:443
2025-08-29 13:22:02,914 - DEBUG - Starting new HTTPS connection (1): bandcamp.com:443
2025-08-29 13:22:03,425 - ERROR - Error in worker thread for check_username: maximum recursion depth exceeded while calling a Python object
Traceback (most recent call last):
  File "C:\Users\mikromark\Desktop\laitoxx 2.2.1\gui.py", line 378, in run_tool
    with contextlib.redirect_stdout(output_stream): self.func()
                                                    ^^^^^^^^^^^
  File "C:\Users\mikromark\Desktop\laitoxx 2.2.1\script\tools\user_checker.py", line 71, in check_username
    platform, url = future.result()
                    ^^^^^^^^^^^^^^^
  File "C:\Users\mikromark\AppData\Local\Programs\Python\Python311\Lib\concurrent\futures\_base.py", line 449, in result
    return self.__get_result()
           ^^^^^^^^^^^^^^^^^^^
  File "C:\Users\mikromark\AppData\Local\Programs\Python\Python311\Lib\concurrent\futures\_base.py", line 401, in __get_result
    raise self._exception
  File "C:\Users\mikromark\AppData\Local\Programs\Python\Python311\Lib\concurrent\futures\thread.py", line 58, in run
    result = self.fn(*self.args, **self.kwargs)
             ^^^^^^^^^^^^^^^^^^^^^^^^^^^^^^^^^^
  File "C:\Users\mikromark\Desktop\laitoxx 2.2.1\script\tools\user_checker.py", line 11, in check_platform
    response = session.get(url, headers=headers, timeout=10, allow_redirects=True)
               ^^^^^^^^^^^^^^^^^^^^^^^^^^^^^^^^^^^^^^^^^^^^^^^^^^^^^^^^^^^^^^^^^^^
  File "C:\Users\mikromark\AppData\Local\Programs\Python\Python311\Lib\site-packages\requests\sessions.py", line 602, in get
    return self.request("GET", url, **kwargs)
           ^^^^^^^^^^^^^^^^^^^^^^^^^^^^^^^^^^
  File "C:\Users\mikromark\AppData\Local\Programs\Python\Python311\Lib\site-packages\requests\sessions.py", line 589, in request
    resp = self.send(prep, **send_kwargs)
           ^^^^^^^^^^^^^^^^^^^^^^^^^^^^^^
  File "C:\Users\mikromark\AppData\Local\Programs\Python\Python311\Lib\site-packages\requests\sessions.py", line 703, in send
    r = adapter.send(request, **kwargs)
        ^^^^^^^^^^^^^^^^^^^^^^^^^^^^^^^
  File "C:\Users\mikromark\AppData\Local\Programs\Python\Python311\Lib\site-packages\requests\adapters.py", line 644, in send
    resp = conn.urlopen(
           ^^^^^^^^^^^^^
  File "C:\Users\mikromark\AppData\Local\Programs\Python\Python311\Lib\site-packages\urllib3\connectionpool.py", line 787, in urlopen
    response = self._make_request(
               ^^^^^^^^^^^^^^^^^^^
  File "C:\Users\mikromark\AppData\Local\Programs\Python\Python311\Lib\site-packages\urllib3\connectionpool.py", line 464, in _make_request
    self._validate_conn(conn)
  File "C:\Users\mikromark\AppData\Local\Programs\Python\Python311\Lib\site-packages\urllib3\connectionpool.py", line 1093, in _validate_conn
    conn.connect()
  File "C:\Users\mikromark\AppData\Local\Programs\Python\Python311\Lib\site-packages\urllib3\connection.py", line 790, in connect
    sock_and_verified = _ssl_wrap_socket_and_match_hostname(
                        ^^^^^^^^^^^^^^^^^^^^^^^^^^^^^^^^^^^^
  File "C:\Users\mikromark\AppData\Local\Programs\Python\Python311\Lib\site-packages\urllib3\connection.py", line 922, in _ssl_wrap_socket_and_match_hostname
    context = create_urllib3_context(
              ^^^^^^^^^^^^^^^^^^^^^^^
  File "C:\Users\mikromark\AppData\Local\Programs\Python\Python311\Lib\site-packages\urllib3\util\ssl_.py", line 303, in create_urllib3_context
    context.minimum_version = TLSVersion.TLSv1_2
    ^^^^^^^^^^^^^^^^^^^^^^^
  File "C:\Users\mikromark\AppData\Local\Programs\Python\Python311\Lib\ssl.py", line 608, in minimum_version
    super(SSLContext, SSLContext).minimum_version.__set__(self, value)
  File "C:\Users\mikromark\AppData\Local\Programs\Python\Python311\Lib\ssl.py", line 608, in minimum_version
    super(SSLContext, SSLContext).minimum_version.__set__(self, value)
  File "C:\Users\mikromark\AppData\Local\Programs\Python\Python311\Lib\ssl.py", line 608, in minimum_version
    super(SSLContext, SSLContext).minimum_version.__set__(self, value)
  [Previous line repeated 479 more times]
  File "C:\Users\mikromark\AppData\Local\Programs\Python\Python311\Lib\ssl.py", line 606, in minimum_version
    if value == TLSVersion.SSLv3:
                ^^^^^^^^^^^^^^^^
  File "C:\Users\mikromark\AppData\Local\Programs\Python\Python311\Lib\enum.py", line 191, in __get__
    return ownerclass._member_map_[self.name]
           ^^^^^^^^^^^^^^^^^^^^^^^
RecursionError: maximum recursion depth exceeded while calling a Python object
2025-08-29 13:22:22,220 - DEBUG - Starting new HTTP connection (1): laitoxx.su:80
2025-08-29 13:22:22,483 - DEBUG - http://laitoxx.su:80 "GET / HTTP/1.1" 301 None
2025-08-29 13:22:22,485 - DEBUG - Starting new HTTPS connection (1): laitoxx.su:443
2025-08-29 13:22:22,554 - ERROR - Error in worker thread for web_crawler: maximum recursion depth exceeded while calling a Python object
Traceback (most recent call last):
  File "C:\Users\mikromark\Desktop\laitoxx 2.2.1\gui.py", line 378, in run_tool
    with contextlib.redirect_stdout(output_stream): self.func()
                                                    ^^^^^^^^^^^
  File "C:\Users\mikromark\Desktop\laitoxx 2.2.1\script\tools\web_crawler.py", line 53, in web_crawler
    new_links = get_all_links(session, url)
                ^^^^^^^^^^^^^^^^^^^^^^^^^^^
  File "C:\Users\mikromark\Desktop\laitoxx 2.2.1\script\tools\web_crawler.py", line 9, in get_all_links
    response = session.get(url, timeout=10)
               ^^^^^^^^^^^^^^^^^^^^^^^^^^^^
  File "C:\Users\mikromark\AppData\Local\Programs\Python\Python311\Lib\site-packages\requests\sessions.py", line 602, in get
    return self.request("GET", url, **kwargs)
           ^^^^^^^^^^^^^^^^^^^^^^^^^^^^^^^^^^
  File "C:\Users\mikromark\AppData\Local\Programs\Python\Python311\Lib\site-packages\requests\sessions.py", line 589, in request
    resp = self.send(prep, **send_kwargs)
           ^^^^^^^^^^^^^^^^^^^^^^^^^^^^^^
  File "C:\Users\mikromark\AppData\Local\Programs\Python\Python311\Lib\site-packages\requests\sessions.py", line 724, in send
    history = [resp for resp in gen]
              ^^^^^^^^^^^^^^^^^^^^^^
  File "C:\Users\mikromark\AppData\Local\Programs\Python\Python311\Lib\site-packages\requests\sessions.py", line 724, in <listcomp>
    history = [resp for resp in gen]
              ^^^^^^^^^^^^^^^^^^^^^^
  File "C:\Users\mikromark\AppData\Local\Programs\Python\Python311\Lib\site-packages\requests\sessions.py", line 265, in resolve_redirects
    resp = self.send(
           ^^^^^^^^^^
  File "C:\Users\mikromark\AppData\Local\Programs\Python\Python311\Lib\site-packages\requests\sessions.py", line 703, in send
    r = adapter.send(request, **kwargs)
        ^^^^^^^^^^^^^^^^^^^^^^^^^^^^^^^
  File "C:\Users\mikromark\AppData\Local\Programs\Python\Python311\Lib\site-packages\requests\adapters.py", line 644, in send
    resp = conn.urlopen(
           ^^^^^^^^^^^^^
  File "C:\Users\mikromark\AppData\Local\Programs\Python\Python311\Lib\site-packages\urllib3\connectionpool.py", line 787, in urlopen
    response = self._make_request(
               ^^^^^^^^^^^^^^^^^^^
  File "C:\Users\mikromark\AppData\Local\Programs\Python\Python311\Lib\site-packages\urllib3\connectionpool.py", line 464, in _make_request
    self._validate_conn(conn)
  File "C:\Users\mikromark\AppData\Local\Programs\Python\Python311\Lib\site-packages\urllib3\connectionpool.py", line 1093, in _validate_conn
    conn.connect()
  File "C:\Users\mikromark\AppData\Local\Programs\Python\Python311\Lib\site-packages\urllib3\connection.py", line 790, in connect
    sock_and_verified = _ssl_wrap_socket_and_match_hostname(
                        ^^^^^^^^^^^^^^^^^^^^^^^^^^^^^^^^^^^^
  File "C:\Users\mikromark\AppData\Local\Programs\Python\Python311\Lib\site-packages\urllib3\connection.py", line 922, in _ssl_wrap_socket_and_match_hostname
    context = create_urllib3_context(
              ^^^^^^^^^^^^^^^^^^^^^^^
  File "C:\Users\mikromark\AppData\Local\Programs\Python\Python311\Lib\site-packages\urllib3\util\ssl_.py", line 303, in create_urllib3_context
    context.minimum_version = TLSVersion.TLSv1_2
    ^^^^^^^^^^^^^^^^^^^^^^^
  File "C:\Users\mikromark\AppData\Local\Programs\Python\Python311\Lib\ssl.py", line 608, in minimum_version
    super(SSLContext, SSLContext).minimum_version.__set__(self, value)
  File "C:\Users\mikromark\AppData\Local\Programs\Python\Python311\Lib\ssl.py", line 608, in minimum_version
    super(SSLContext, SSLContext).minimum_version.__set__(self, value)
  File "C:\Users\mikromark\AppData\Local\Programs\Python\Python311\Lib\ssl.py", line 608, in minimum_version
    super(SSLContext, SSLContext).minimum_version.__set__(self, value)
  [Previous line repeated 487 more times]
  File "C:\Users\mikromark\AppData\Local\Programs\Python\Python311\Lib\ssl.py", line 606, in minimum_version
    if value == TLSVersion.SSLv3:
                ^^^^^^^^^^^^^^^^
  File "C:\Users\mikromark\AppData\Local\Programs\Python\Python311\Lib\enum.py", line 191, in __get__
    return ownerclass._member_map_[self.name]
           ^^^^^^^^^^^^^^^^^^^^^^^
RecursionError: maximum recursion depth exceeded while calling a Python object
2025-08-29 13:22:27,186 - DEBUG - Starting new HTTP connection (1): google.com:80
2025-08-29 13:22:27,284 - DEBUG - http://google.com:80 "GET / HTTP/1.1" 301 219
2025-08-29 13:22:27,287 - DEBUG - Starting new HTTP connection (1): www.google.com:80
2025-08-29 13:22:27,565 - DEBUG - http://www.google.com:80 "GET / HTTP/1.1" 200 None
2025-08-29 13:22:27,613 - DEBUG - http://google.com:80 "GET /intl/ru/ads/ HTTP/1.1" 301 232
2025-08-29 13:22:27,614 - DEBUG - Starting new HTTPS connection (1): www.google.com:443
2025-08-29 13:22:27,650 - ERROR - Error in worker thread for web_crawler: maximum recursion depth exceeded while calling a Python object
Traceback (most recent call last):
  File "C:\Users\mikromark\Desktop\laitoxx 2.2.1\gui.py", line 378, in run_tool
    with contextlib.redirect_stdout(output_stream): self.func()
                                                    ^^^^^^^^^^^
  File "C:\Users\mikromark\Desktop\laitoxx 2.2.1\script\tools\web_crawler.py", line 53, in web_crawler
    new_links = get_all_links(session, url)
                ^^^^^^^^^^^^^^^^^^^^^^^^^^^
  File "C:\Users\mikromark\Desktop\laitoxx 2.2.1\script\tools\web_crawler.py", line 9, in get_all_links
    response = session.get(url, timeout=10)
               ^^^^^^^^^^^^^^^^^^^^^^^^^^^^
  File "C:\Users\mikromark\AppData\Local\Programs\Python\Python311\Lib\site-packages\requests\sessions.py", line 602, in get
    return self.request("GET", url, **kwargs)
           ^^^^^^^^^^^^^^^^^^^^^^^^^^^^^^^^^^
  File "C:\Users\mikromark\AppData\Local\Programs\Python\Python311\Lib\site-packages\requests\sessions.py", line 589, in request
    resp = self.send(prep, **send_kwargs)
           ^^^^^^^^^^^^^^^^^^^^^^^^^^^^^^
  File "C:\Users\mikromark\AppData\Local\Programs\Python\Python311\Lib\site-packages\requests\sessions.py", line 724, in send
    history = [resp for resp in gen]
              ^^^^^^^^^^^^^^^^^^^^^^
  File "C:\Users\mikromark\AppData\Local\Programs\Python\Python311\Lib\site-packages\requests\sessions.py", line 724, in <listcomp>
    history = [resp for resp in gen]
              ^^^^^^^^^^^^^^^^^^^^^^
  File "C:\Users\mikromark\AppData\Local\Programs\Python\Python311\Lib\site-packages\requests\sessions.py", line 265, in resolve_redirects
    resp = self.send(
           ^^^^^^^^^^
  File "C:\Users\mikromark\AppData\Local\Programs\Python\Python311\Lib\site-packages\requests\sessions.py", line 703, in send
    r = adapter.send(request, **kwargs)
        ^^^^^^^^^^^^^^^^^^^^^^^^^^^^^^^
  File "C:\Users\mikromark\AppData\Local\Programs\Python\Python311\Lib\site-packages\requests\adapters.py", line 644, in send
    resp = conn.urlopen(
           ^^^^^^^^^^^^^
  File "C:\Users\mikromark\AppData\Local\Programs\Python\Python311\Lib\site-packages\urllib3\connectionpool.py", line 787, in urlopen
    response = self._make_request(
               ^^^^^^^^^^^^^^^^^^^
  File "C:\Users\mikromark\AppData\Local\Programs\Python\Python311\Lib\site-packages\urllib3\connectionpool.py", line 464, in _make_request
    self._validate_conn(conn)
  File "C:\Users\mikromark\AppData\Local\Programs\Python\Python311\Lib\site-packages\urllib3\connectionpool.py", line 1093, in _validate_conn
    conn.connect()
  File "C:\Users\mikromark\AppData\Local\Programs\Python\Python311\Lib\site-packages\urllib3\connection.py", line 790, in connect
    sock_and_verified = _ssl_wrap_socket_and_match_hostname(
                        ^^^^^^^^^^^^^^^^^^^^^^^^^^^^^^^^^^^^
  File "C:\Users\mikromark\AppData\Local\Programs\Python\Python311\Lib\site-packages\urllib3\connection.py", line 922, in _ssl_wrap_socket_and_match_hostname
    context = create_urllib3_context(
              ^^^^^^^^^^^^^^^^^^^^^^^
  File "C:\Users\mikromark\AppData\Local\Programs\Python\Python311\Lib\site-packages\urllib3\util\ssl_.py", line 303, in create_urllib3_context
    context.minimum_version = TLSVersion.TLSv1_2
    ^^^^^^^^^^^^^^^^^^^^^^^
  File "C:\Users\mikromark\AppData\Local\Programs\Python\Python311\Lib\ssl.py", line 608, in minimum_version
    super(SSLContext, SSLContext).minimum_version.__set__(self, value)
  File "C:\Users\mikromark\AppData\Local\Programs\Python\Python311\Lib\ssl.py", line 608, in minimum_version
    super(SSLContext, SSLContext).minimum_version.__set__(self, value)
  File "C:\Users\mikromark\AppData\Local\Programs\Python\Python311\Lib\ssl.py", line 608, in minimum_version
    super(SSLContext, SSLContext).minimum_version.__set__(self, value)
  [Previous line repeated 487 more times]
  File "C:\Users\mikromark\AppData\Local\Programs\Python\Python311\Lib\ssl.py", line 606, in minimum_version
    if value == TLSVersion.SSLv3:
                ^^^^^^^^^^^^^^^^
  File "C:\Users\mikromark\AppData\Local\Programs\Python\Python311\Lib\enum.py", line 191, in __get__
    return ownerclass._member_map_[self.name]
           ^^^^^^^^^^^^^^^^^^^^^^^
RecursionError: maximum recursion depth exceeded while calling a Python object
2025-08-29 13:22:58,108 - DEBUG - Starting new HTTP connection (1): laitoxx.su:80
2025-08-29 13:22:58,327 - DEBUG - http://laitoxx.su:80 "GET / HTTP/1.1" 301 None
2025-08-29 13:22:58,328 - DEBUG - Starting new HTTPS connection (1): laitoxx.su:443
2025-08-29 13:22:58,402 - ERROR - Error in worker thread for check_site: maximum recursion depth exceeded while calling a Python object
Traceback (most recent call last):
  File "C:\Users\mikromark\Desktop\laitoxx 2.2.1\gui.py", line 378, in run_tool
    with contextlib.redirect_stdout(output_stream): self.func()
                                                    ^^^^^^^^^^^
  File "C:\Users\mikromark\Desktop\laitoxx 2.2.1\script\tools\site_checker.py", line 29, in check_site
    response = requests.get(url, timeout=10, allow_redirects=True)
               ^^^^^^^^^^^^^^^^^^^^^^^^^^^^^^^^^^^^^^^^^^^^^^^^^^^
  File "C:\Users\mikromark\AppData\Local\Programs\Python\Python311\Lib\site-packages\requests\api.py", line 73, in get
    return request("get", url, params=params, **kwargs)
           ^^^^^^^^^^^^^^^^^^^^^^^^^^^^^^^^^^^^^^^^^^^^
  File "C:\Users\mikromark\AppData\Local\Programs\Python\Python311\Lib\site-packages\requests\api.py", line 59, in request
    return session.request(method=method, url=url, **kwargs)
           ^^^^^^^^^^^^^^^^^^^^^^^^^^^^^^^^^^^^^^^^^^^^^^^^^
  File "C:\Users\mikromark\AppData\Local\Programs\Python\Python311\Lib\site-packages\requests\sessions.py", line 589, in request
    resp = self.send(prep, **send_kwargs)
           ^^^^^^^^^^^^^^^^^^^^^^^^^^^^^^
  File "C:\Users\mikromark\AppData\Local\Programs\Python\Python311\Lib\site-packages\requests\sessions.py", line 724, in send
    history = [resp for resp in gen]
              ^^^^^^^^^^^^^^^^^^^^^^
  File "C:\Users\mikromark\AppData\Local\Programs\Python\Python311\Lib\site-packages\requests\sessions.py", line 724, in <listcomp>
    history = [resp for resp in gen]
              ^^^^^^^^^^^^^^^^^^^^^^
  File "C:\Users\mikromark\AppData\Local\Programs\Python\Python311\Lib\site-packages\requests\sessions.py", line 265, in resolve_redirects
    resp = self.send(
           ^^^^^^^^^^
  File "C:\Users\mikromark\AppData\Local\Programs\Python\Python311\Lib\site-packages\requests\sessions.py", line 703, in send
    r = adapter.send(request, **kwargs)
        ^^^^^^^^^^^^^^^^^^^^^^^^^^^^^^^
  File "C:\Users\mikromark\AppData\Local\Programs\Python\Python311\Lib\site-packages\requests\adapters.py", line 644, in send
    resp = conn.urlopen(
           ^^^^^^^^^^^^^
  File "C:\Users\mikromark\AppData\Local\Programs\Python\Python311\Lib\site-packages\urllib3\connectionpool.py", line 787, in urlopen
    response = self._make_request(
               ^^^^^^^^^^^^^^^^^^^
  File "C:\Users\mikromark\AppData\Local\Programs\Python\Python311\Lib\site-packages\urllib3\connectionpool.py", line 464, in _make_request
    self._validate_conn(conn)
  File "C:\Users\mikromark\AppData\Local\Programs\Python\Python311\Lib\site-packages\urllib3\connectionpool.py", line 1093, in _validate_conn
    conn.connect()
  File "C:\Users\mikromark\AppData\Local\Programs\Python\Python311\Lib\site-packages\urllib3\connection.py", line 790, in connect
    sock_and_verified = _ssl_wrap_socket_and_match_hostname(
                        ^^^^^^^^^^^^^^^^^^^^^^^^^^^^^^^^^^^^
  File "C:\Users\mikromark\AppData\Local\Programs\Python\Python311\Lib\site-packages\urllib3\connection.py", line 922, in _ssl_wrap_socket_and_match_hostname
    context = create_urllib3_context(
              ^^^^^^^^^^^^^^^^^^^^^^^
  File "C:\Users\mikromark\AppData\Local\Programs\Python\Python311\Lib\site-packages\urllib3\util\ssl_.py", line 303, in create_urllib3_context
    context.minimum_version = TLSVersion.TLSv1_2
    ^^^^^^^^^^^^^^^^^^^^^^^
  File "C:\Users\mikromark\AppData\Local\Programs\Python\Python311\Lib\ssl.py", line 608, in minimum_version
    super(SSLContext, SSLContext).minimum_version.__set__(self, value)
  File "C:\Users\mikromark\AppData\Local\Programs\Python\Python311\Lib\ssl.py", line 608, in minimum_version
    super(SSLContext, SSLContext).minimum_version.__set__(self, value)
  File "C:\Users\mikromark\AppData\Local\Programs\Python\Python311\Lib\ssl.py", line 608, in minimum_version
    super(SSLContext, SSLContext).minimum_version.__set__(self, value)
  [Previous line repeated 487 more times]
  File "C:\Users\mikromark\AppData\Local\Programs\Python\Python311\Lib\ssl.py", line 606, in minimum_version
    if value == TLSVersion.SSLv3:
                ^^^^^^^^^^^^^^^^
  File "C:\Users\mikromark\AppData\Local\Programs\Python\Python311\Lib\enum.py", line 191, in __get__
    return ownerclass._member_map_[self.name]
           ^^^^^^^^^^^^^^^^^^^^^^^
RecursionError: maximum recursion depth exceeded while calling a Python object
2025-08-29 13:23:30,484 - DEBUG - Starting new HTTPS connection (1): laitoxx.su:443
2025-08-29 13:23:30,558 - ERROR - Error in worker thread for check_url: maximum recursion depth exceeded
Traceback (most recent call last):
  File "C:\Users\mikromark\Desktop\laitoxx 2.2.1\gui.py", line 378, in run_tool
    with contextlib.redirect_stdout(output_stream): self.func()
                                                    ^^^^^^^^^^^
  File "C:\Users\mikromark\Desktop\laitoxx 2.2.1\script\tools\url_checker.py", line 7, in check_url
    response = requests.get(url, timeout=10, allow_redirects=True)
               ^^^^^^^^^^^^^^^^^^^^^^^^^^^^^^^^^^^^^^^^^^^^^^^^^^^
  File "C:\Users\mikromark\AppData\Local\Programs\Python\Python311\Lib\site-packages\requests\api.py", line 73, in get
    return request("get", url, params=params, **kwargs)
           ^^^^^^^^^^^^^^^^^^^^^^^^^^^^^^^^^^^^^^^^^^^^
  File "C:\Users\mikromark\AppData\Local\Programs\Python\Python311\Lib\site-packages\requests\api.py", line 59, in request
    return session.request(method=method, url=url, **kwargs)
           ^^^^^^^^^^^^^^^^^^^^^^^^^^^^^^^^^^^^^^^^^^^^^^^^^
  File "C:\Users\mikromark\AppData\Local\Programs\Python\Python311\Lib\site-packages\requests\sessions.py", line 589, in request
    resp = self.send(prep, **send_kwargs)
           ^^^^^^^^^^^^^^^^^^^^^^^^^^^^^^
  File "C:\Users\mikromark\AppData\Local\Programs\Python\Python311\Lib\site-packages\requests\sessions.py", line 703, in send
    r = adapter.send(request, **kwargs)
        ^^^^^^^^^^^^^^^^^^^^^^^^^^^^^^^
  File "C:\Users\mikromark\AppData\Local\Programs\Python\Python311\Lib\site-packages\requests\adapters.py", line 644, in send
    resp = conn.urlopen(
           ^^^^^^^^^^^^^
  File "C:\Users\mikromark\AppData\Local\Programs\Python\Python311\Lib\site-packages\urllib3\connectionpool.py", line 787, in urlopen
    response = self._make_request(
               ^^^^^^^^^^^^^^^^^^^
  File "C:\Users\mikromark\AppData\Local\Programs\Python\Python311\Lib\site-packages\urllib3\connectionpool.py", line 464, in _make_request
    self._validate_conn(conn)
  File "C:\Users\mikromark\AppData\Local\Programs\Python\Python311\Lib\site-packages\urllib3\connectionpool.py", line 1093, in _validate_conn
    conn.connect()
  File "C:\Users\mikromark\AppData\Local\Programs\Python\Python311\Lib\site-packages\urllib3\connection.py", line 790, in connect
    sock_and_verified = _ssl_wrap_socket_and_match_hostname(
                        ^^^^^^^^^^^^^^^^^^^^^^^^^^^^^^^^^^^^
  File "C:\Users\mikromark\AppData\Local\Programs\Python\Python311\Lib\site-packages\urllib3\connection.py", line 922, in _ssl_wrap_socket_and_match_hostname
    context = create_urllib3_context(
              ^^^^^^^^^^^^^^^^^^^^^^^
  File "C:\Users\mikromark\AppData\Local\Programs\Python\Python311\Lib\site-packages\urllib3\util\ssl_.py", line 303, in create_urllib3_context
    context.minimum_version = TLSVersion.TLSv1_2
    ^^^^^^^^^^^^^^^^^^^^^^^
  File "C:\Users\mikromark\AppData\Local\Programs\Python\Python311\Lib\ssl.py", line 608, in minimum_version
    super(SSLContext, SSLContext).minimum_version.__set__(self, value)
  File "C:\Users\mikromark\AppData\Local\Programs\Python\Python311\Lib\ssl.py", line 608, in minimum_version
    super(SSLContext, SSLContext).minimum_version.__set__(self, value)
  File "C:\Users\mikromark\AppData\Local\Programs\Python\Python311\Lib\ssl.py", line 608, in minimum_version
    super(SSLContext, SSLContext).minimum_version.__set__(self, value)
  [Previous line repeated 489 more times]
  File "C:\Users\mikromark\AppData\Local\Programs\Python\Python311\Lib\ssl.py", line 606, in minimum_version
    if value == TLSVersion.SSLv3:
                ^^^^^^^^^^^^^^^^
RecursionError: maximum recursion depth exceeded
2025-08-29 13:23:57,894 - DEBUG - Starting new HTTP connection (1): laitoxx.su:80
2025-08-29 13:23:57,896 - DEBUG - Starting new HTTP connection (2): laitoxx.su:80
2025-08-29 13:23:57,897 - DEBUG - Starting new HTTP connection (3): laitoxx.su:80
2025-08-29 13:23:57,899 - DEBUG - Starting new HTTP connection (4): laitoxx.su:80
2025-08-29 13:23:57,901 - DEBUG - Starting new HTTP connection (5): laitoxx.su:80
2025-08-29 13:23:57,902 - DEBUG - Starting new HTTP connection (6): laitoxx.su:80
2025-08-29 13:23:57,903 - DEBUG - Starting new HTTP connection (7): laitoxx.su:80
2025-08-29 13:23:57,905 - DEBUG - Starting new HTTP connection (8): laitoxx.su:80
2025-08-29 13:23:57,906 - DEBUG - Starting new HTTP connection (9): laitoxx.su:80
2025-08-29 13:23:57,907 - DEBUG - Starting new HTTP connection (10): laitoxx.su:80
2025-08-29 13:23:58,098 - DEBUG - http://laitoxx.su:80 "GET /admin/ HTTP/1.1" 301 None
2025-08-29 13:23:58,100 - DEBUG - Starting new HTTPS connection (1): laitoxx.su:443
2025-08-29 13:23:58,108 - DEBUG - http://laitoxx.su:80 "GET /admin-area/ HTTP/1.1" 301 None
2025-08-29 13:23:58,109 - DEBUG - Starting new HTTPS connection (2): laitoxx.su:443
2025-08-29 13:23:58,111 - DEBUG - http://laitoxx.su:80 "GET /admin_panel/ HTTP/1.1" 301 None
2025-08-29 13:23:58,112 - DEBUG - Starting new HTTPS connection (3): laitoxx.su:443
2025-08-29 13:23:58,113 - DEBUG - http://laitoxx.su:80 "GET /admincp/ HTTP/1.1" 301 None
2025-08-29 13:23:58,115 - DEBUG - Starting new HTTPS connection (4): laitoxx.su:443
2025-08-29 13:23:58,116 - DEBUG - http://laitoxx.su:80 "GET /admin/login.php HTTP/1.1" 301 None
2025-08-29 13:23:58,117 - DEBUG - Starting new HTTPS connection (5): laitoxx.su:443
2025-08-29 13:23:58,118 - DEBUG - http://laitoxx.su:80 "GET /admin.php HTTP/1.1" 301 None
2025-08-29 13:23:58,119 - DEBUG - Starting new HTTPS connection (6): laitoxx.su:443
2025-08-29 13:23:58,121 - DEBUG - http://laitoxx.su:80 "GET /administrator/ HTTP/1.1" 301 None
2025-08-29 13:23:58,122 - DEBUG - Starting new HTTPS connection (7): laitoxx.su:443
2025-08-29 13:23:58,123 - DEBUG - http://laitoxx.su:80 "GET /login.php HTTP/1.1" 301 None
2025-08-29 13:23:58,124 - DEBUG - Starting new HTTPS connection (8): laitoxx.su:443
2025-08-29 13:23:58,125 - DEBUG - http://laitoxx.su:80 "GET /admin/index.php HTTP/1.1" 301 None
2025-08-29 13:23:58,127 - DEBUG - Starting new HTTPS connection (9): laitoxx.su:443
2025-08-29 13:23:58,134 - DEBUG - http://laitoxx.su:80 "GET /admin_login.php HTTP/1.1" 301 None
2025-08-29 13:23:58,136 - DEBUG - Starting new HTTPS connection (10): laitoxx.su:443
2025-08-29 13:23:58,166 - DEBUG - Starting new HTTP connection (1): laitoxx.su:80
2025-08-29 13:23:58,185 - DEBUG - Starting new HTTP connection (2): laitoxx.su:80
2025-08-29 13:23:58,187 - DEBUG - Starting new HTTP connection (3): laitoxx.su:80
2025-08-29 13:23:58,191 - DEBUG - Starting new HTTP connection (4): laitoxx.su:80
2025-08-29 13:23:58,192 - DEBUG - Starting new HTTP connection (5): laitoxx.su:80
2025-08-29 13:23:58,196 - DEBUG - Starting new HTTP connection (6): laitoxx.su:80
2025-08-29 13:23:58,198 - DEBUG - Starting new HTTP connection (7): laitoxx.su:80
2025-08-29 13:23:58,201 - DEBUG - Starting new HTTP connection (8): laitoxx.su:80
2025-08-29 13:23:58,202 - DEBUG - Starting new HTTP connection (9): laitoxx.su:80
2025-08-29 13:23:58,205 - DEBUG - Starting new HTTP connection (10): laitoxx.su:80
2025-08-29 13:23:58,327 - DEBUG - http://laitoxx.su:80 "GET /user.php HTTP/1.1" 301 None
2025-08-29 13:23:58,331 - DEBUG - Starting new HTTPS connection (1): laitoxx.su:443
2025-08-29 13:23:58,360 - DEBUG - http://laitoxx.su:80 "GET /dashboard/ HTTP/1.1" 301 None
2025-08-29 13:23:58,363 - DEBUG - Starting new HTTPS connection (2): laitoxx.su:443
2025-08-29 13:23:58,368 - DEBUG - http://laitoxx.su:80 "GET /admin/home.php HTTP/1.1" 301 None
2025-08-29 13:23:58,370 - DEBUG - Starting new HTTPS connection (3): laitoxx.su:443
2025-08-29 13:23:58,373 - DEBUG - http://laitoxx.su:80 "GET /controlpanel/ HTTP/1.1" 301 None
2025-08-29 13:23:58,374 - DEBUG - Starting new HTTPS connection (4): laitoxx.su:443
2025-08-29 13:23:58,375 - DEBUG - http://laitoxx.su:80 "GET /panel/ HTTP/1.1" 301 None
2025-08-29 13:23:58,376 - DEBUG - Starting new HTTPS connection (5): laitoxx.su:443
2025-08-29 13:23:58,377 - DEBUG - http://laitoxx.su:80 "GET /manage/ HTTP/1.1" 301 None
2025-08-29 13:23:58,378 - DEBUG - Starting new HTTPS connection (6): laitoxx.su:443
2025-08-29 13:23:58,379 - DEBUG - http://laitoxx.su:80 "GET /admin1/ HTTP/1.1" 301 None
2025-08-29 13:23:58,381 - DEBUG - Starting new HTTPS connection (7): laitoxx.su:443
2025-08-29 13:23:58,383 - DEBUG - http://laitoxx.su:80 "GET /admin/account.php HTTP/1.1" 301 None
2025-08-29 13:23:58,383 - DEBUG - Starting new HTTPS connection (8): laitoxx.su:443
2025-08-29 13:23:58,399 - DEBUG - http://laitoxx.su:80 "GET /cpanel/ HTTP/1.1" 301 None
2025-08-29 13:23:58,400 - DEBUG - Starting new HTTPS connection (9): laitoxx.su:443
2025-08-29 13:23:58,404 - DEBUG - http://laitoxx.su:80 "GET /backend/ HTTP/1.1" 301 None
2025-08-29 13:23:58,405 - DEBUG - Starting new HTTPS connection (10): laitoxx.su:443
2025-08-29 13:23:58,509 - DEBUG - http://laitoxx.su:80 "GET /admin2/ HTTP/1.1" 301 None
2025-08-29 13:23:58,510 - DEBUG - Starting new HTTPS connection (11): laitoxx.su:443
2025-08-29 13:23:58,601 - DEBUG - http://laitoxx.su:80 "GET /moderator/ HTTP/1.1" 301 None
2025-08-29 13:23:58,604 - DEBUG - Starting new HTTPS connection (12): laitoxx.su:443
2025-08-29 13:23:58,609 - DEBUG - http://laitoxx.su:80 "GET /siteadmin/ HTTP/1.1" 301 None
2025-08-29 13:23:58,611 - DEBUG - Starting new HTTPS connection (13): laitoxx.su:443
2025-08-29 13:23:58,611 - DEBUG - http://laitoxx.su:80 "GET /login/ HTTP/1.1" 301 None
2025-08-29 13:23:58,613 - DEBUG - Starting new HTTPS connection (14): laitoxx.su:443
2025-08-29 13:23:58,614 - DEBUG - http://laitoxx.su:80 "GET /webadmin/ HTTP/1.1" 301 None
2025-08-29 13:23:58,615 - DEBUG - Starting new HTTPS connection (15): laitoxx.su:443
2025-08-29 13:23:58,617 - DEBUG - http://laitoxx.su:80 "GET /auth/ HTTP/1.1" 301 None
2025-08-29 13:23:58,618 - DEBUG - Starting new HTTPS connection (16): laitoxx.su:443
2025-08-29 13:23:58,619 - DEBUG - http://laitoxx.su:80 "GET /signin/ HTTP/1.1" 301 None
2025-08-29 13:23:58,621 - DEBUG - Starting new HTTPS connection (17): laitoxx.su:443
2025-08-29 13:23:58,624 - DEBUG - http://laitoxx.su:80 "GET /wp-login.php HTTP/1.1" 301 None
2025-08-29 13:23:58,625 - DEBUG - Starting new HTTPS connection (18): laitoxx.su:443
2025-08-29 13:23:58,627 - DEBUG - http://laitoxx.su:80 "GET /wp-admin/ HTTP/1.1" 301 None
2025-08-29 13:23:58,628 - DEBUG - Starting new HTTPS connection (19): laitoxx.su:443
2025-08-29 13:23:58,695 - ERROR - Error in worker thread for find_admin_panel: maximum recursion depth exceeded
Traceback (most recent call last):
  File "C:\Users\mikromark\Desktop\laitoxx 2.2.1\gui.py", line 378, in run_tool
    with contextlib.redirect_stdout(output_stream): self.func()
                                                    ^^^^^^^^^^^
  File "C:\Users\mikromark\Desktop\laitoxx 2.2.1\script\tools\admin_finder.py", line 42, in find_admin_panel
    result = future.result()
             ^^^^^^^^^^^^^^^
  File "C:\Users\mikromark\AppData\Local\Programs\Python\Python311\Lib\concurrent\futures\_base.py", line 449, in result
    return self.__get_result()
           ^^^^^^^^^^^^^^^^^^^
  File "C:\Users\mikromark\AppData\Local\Programs\Python\Python311\Lib\concurrent\futures\_base.py", line 401, in __get_result
    raise self._exception
  File "C:\Users\mikromark\AppData\Local\Programs\Python\Python311\Lib\concurrent\futures\thread.py", line 58, in run
    result = self.fn(*self.args, **self.kwargs)
             ^^^^^^^^^^^^^^^^^^^^^^^^^^^^^^^^^^
  File "C:\Users\mikromark\Desktop\laitoxx 2.2.1\script\tools\admin_finder.py", line 9, in check_path
    response = session.get(full_url, timeout=5, allow_redirects=True)
               ^^^^^^^^^^^^^^^^^^^^^^^^^^^^^^^^^^^^^^^^^^^^^^^^^^^^^^
  File "C:\Users\mikromark\AppData\Local\Programs\Python\Python311\Lib\site-packages\requests\sessions.py", line 602, in get
    return self.request("GET", url, **kwargs)
           ^^^^^^^^^^^^^^^^^^^^^^^^^^^^^^^^^^
  File "C:\Users\mikromark\AppData\Local\Programs\Python\Python311\Lib\site-packages\requests\sessions.py", line 589, in request
    resp = self.send(prep, **send_kwargs)
           ^^^^^^^^^^^^^^^^^^^^^^^^^^^^^^
  File "C:\Users\mikromark\AppData\Local\Programs\Python\Python311\Lib\site-packages\requests\sessions.py", line 724, in send
    history = [resp for resp in gen]
              ^^^^^^^^^^^^^^^^^^^^^^
  File "C:\Users\mikromark\AppData\Local\Programs\Python\Python311\Lib\site-packages\requests\sessions.py", line 724, in <listcomp>
    history = [resp for resp in gen]
              ^^^^^^^^^^^^^^^^^^^^^^
  File "C:\Users\mikromark\AppData\Local\Programs\Python\Python311\Lib\site-packages\requests\sessions.py", line 265, in resolve_redirects
    resp = self.send(
           ^^^^^^^^^^
  File "C:\Users\mikromark\AppData\Local\Programs\Python\Python311\Lib\site-packages\requests\sessions.py", line 703, in send
    r = adapter.send(request, **kwargs)
        ^^^^^^^^^^^^^^^^^^^^^^^^^^^^^^^
  File "C:\Users\mikromark\AppData\Local\Programs\Python\Python311\Lib\site-packages\requests\adapters.py", line 644, in send
    resp = conn.urlopen(
           ^^^^^^^^^^^^^
  File "C:\Users\mikromark\AppData\Local\Programs\Python\Python311\Lib\site-packages\urllib3\connectionpool.py", line 787, in urlopen
    response = self._make_request(
               ^^^^^^^^^^^^^^^^^^^
  File "C:\Users\mikromark\AppData\Local\Programs\Python\Python311\Lib\site-packages\urllib3\connectionpool.py", line 464, in _make_request
    self._validate_conn(conn)
  File "C:\Users\mikromark\AppData\Local\Programs\Python\Python311\Lib\site-packages\urllib3\connectionpool.py", line 1093, in _validate_conn
    conn.connect()
  File "C:\Users\mikromark\AppData\Local\Programs\Python\Python311\Lib\site-packages\urllib3\connection.py", line 790, in connect
    sock_and_verified = _ssl_wrap_socket_and_match_hostname(
                        ^^^^^^^^^^^^^^^^^^^^^^^^^^^^^^^^^^^^
  File "C:\Users\mikromark\AppData\Local\Programs\Python\Python311\Lib\site-packages\urllib3\connection.py", line 922, in _ssl_wrap_socket_and_match_hostname
    context = create_urllib3_context(
              ^^^^^^^^^^^^^^^^^^^^^^^
  File "C:\Users\mikromark\AppData\Local\Programs\Python\Python311\Lib\site-packages\urllib3\util\ssl_.py", line 303, in create_urllib3_context
    context.minimum_version = TLSVersion.TLSv1_2
    ^^^^^^^^^^^^^^^^^^^^^^^
  File "C:\Users\mikromark\AppData\Local\Programs\Python\Python311\Lib\ssl.py", line 608, in minimum_version
    super(SSLContext, SSLContext).minimum_version.__set__(self, value)
  File "C:\Users\mikromark\AppData\Local\Programs\Python\Python311\Lib\ssl.py", line 608, in minimum_version
    super(SSLContext, SSLContext).minimum_version.__set__(self, value)
  File "C:\Users\mikromark\AppData\Local\Programs\Python\Python311\Lib\ssl.py", line 608, in minimum_version
    super(SSLContext, SSLContext).minimum_version.__set__(self, value)
  [Previous line repeated 478 more times]
  File "C:\Users\mikromark\AppData\Local\Programs\Python\Python311\Lib\ssl.py", line 606, in minimum_version
    if value == TLSVersion.SSLv3:
                ^^^^^^^^^^^^^^^^
RecursionError: maximum recursion depth exceeded
2025-08-29 13:24:55,835 - DEBUG - Starting new HTTPS connection (1): www.1secmail.com:443
2025-08-29 13:24:56,039 - ERROR - Error in worker thread for temp_mail: maximum recursion depth exceeded while calling a Python object
Traceback (most recent call last):
  File "C:\Users\mikromark\Desktop\laitoxx 2.2.1\gui.py", line 378, in run_tool
    with contextlib.redirect_stdout(output_stream): self.func()
                                                    ^^^^^^^^^^^
  File "C:\Users\mikromark\Desktop\laitoxx 2.2.1\script\tools\temp_mail.py", line 55, in temp_mail
    available_domains = get_domains()
                        ^^^^^^^^^^^^^
  File "C:\Users\mikromark\Desktop\laitoxx 2.2.1\script\tools\temp_mail.py", line 12, in get_domains
    response = requests.get("https://www.1secmail.com/api/v1/?action=getDomainList", headers=headers)
               ^^^^^^^^^^^^^^^^^^^^^^^^^^^^^^^^^^^^^^^^^^^^^^^^^^^^^^^^^^^^^^^^^^^^^^^^^^^^^^^^^^^^^^
  File "C:\Users\mikromark\AppData\Local\Programs\Python\Python311\Lib\site-packages\requests\api.py", line 73, in get
    return request("get", url, params=params, **kwargs)
           ^^^^^^^^^^^^^^^^^^^^^^^^^^^^^^^^^^^^^^^^^^^^
  File "C:\Users\mikromark\AppData\Local\Programs\Python\Python311\Lib\site-packages\requests\api.py", line 59, in request
    return session.request(method=method, url=url, **kwargs)
           ^^^^^^^^^^^^^^^^^^^^^^^^^^^^^^^^^^^^^^^^^^^^^^^^^
  File "C:\Users\mikromark\AppData\Local\Programs\Python\Python311\Lib\site-packages\requests\sessions.py", line 589, in request
    resp = self.send(prep, **send_kwargs)
           ^^^^^^^^^^^^^^^^^^^^^^^^^^^^^^
  File "C:\Users\mikromark\AppData\Local\Programs\Python\Python311\Lib\site-packages\requests\sessions.py", line 703, in send
    r = adapter.send(request, **kwargs)
        ^^^^^^^^^^^^^^^^^^^^^^^^^^^^^^^
  File "C:\Users\mikromark\AppData\Local\Programs\Python\Python311\Lib\site-packages\requests\adapters.py", line 644, in send
    resp = conn.urlopen(
           ^^^^^^^^^^^^^
  File "C:\Users\mikromark\AppData\Local\Programs\Python\Python311\Lib\site-packages\urllib3\connectionpool.py", line 787, in urlopen
    response = self._make_request(
               ^^^^^^^^^^^^^^^^^^^
  File "C:\Users\mikromark\AppData\Local\Programs\Python\Python311\Lib\site-packages\urllib3\connectionpool.py", line 464, in _make_request
    self._validate_conn(conn)
  File "C:\Users\mikromark\AppData\Local\Programs\Python\Python311\Lib\site-packages\urllib3\connectionpool.py", line 1093, in _validate_conn
    conn.connect()
  File "C:\Users\mikromark\AppData\Local\Programs\Python\Python311\Lib\site-packages\urllib3\connection.py", line 790, in connect
    sock_and_verified = _ssl_wrap_socket_and_match_hostname(
                        ^^^^^^^^^^^^^^^^^^^^^^^^^^^^^^^^^^^^
  File "C:\Users\mikromark\AppData\Local\Programs\Python\Python311\Lib\site-packages\urllib3\connection.py", line 922, in _ssl_wrap_socket_and_match_hostname
    context = create_urllib3_context(
              ^^^^^^^^^^^^^^^^^^^^^^^
  File "C:\Users\mikromark\AppData\Local\Programs\Python\Python311\Lib\site-packages\urllib3\util\ssl_.py", line 303, in create_urllib3_context
    context.minimum_version = TLSVersion.TLSv1_2
    ^^^^^^^^^^^^^^^^^^^^^^^
  File "C:\Users\mikromark\AppData\Local\Programs\Python\Python311\Lib\ssl.py", line 608, in minimum_version
    super(SSLContext, SSLContext).minimum_version.__set__(self, value)
  File "C:\Users\mikromark\AppData\Local\Programs\Python\Python311\Lib\ssl.py", line 608, in minimum_version
    super(SSLContext, SSLContext).minimum_version.__set__(self, value)
  File "C:\Users\mikromark\AppData\Local\Programs\Python\Python311\Lib\ssl.py", line 608, in minimum_version
    super(SSLContext, SSLContext).minimum_version.__set__(self, value)
  [Previous line repeated 488 more times]
  File "C:\Users\mikromark\AppData\Local\Programs\Python\Python311\Lib\ssl.py", line 606, in minimum_version
    if value == TLSVersion.SSLv3:
                ^^^^^^^^^^^^^^^^
  File "C:\Users\mikromark\AppData\Local\Programs\Python\Python311\Lib\enum.py", line 191, in __get__
    return ownerclass._member_map_[self.name]
           ^^^^^^^^^^^^^^^^^^^^^^^
RecursionError: maximum recursion depth exceeded while calling a Python object
2025-08-29 13:25:14,757 - INFO - Application starting...
2025-08-29 13:25:17,015 - DEBUG - Starting new HTTPS connection (1): raw.githubusercontent.com:443
